[08/Nov/2017 18:53:52] ERROR [django.request:256] Internal Server Error: /set/
Traceback (most recent call last):
  File "/Library/Python/2.7/site-packages/django/core/handlers/base.py", line 132, in get_response
    response = wrapped_callback(request, *callback_args, **callback_kwargs)
  File "/Users/Fan/Desktop/codes/NTCIRMDB2/assessment/views.py", line 268, in set
    val=ulist
  File "/Library/Python/2.7/site-packages/mongoengine/base/document.py", line 81, in __init__
    raise FieldDoesNotExist(msg)
FieldDoesNotExist: The field 'val' does not exist on the document 'usrlist'
[08/Nov/2017 19:04:40] ERROR [django.request:256] Internal Server Error: /task/
Traceback (most recent call last):
  File "/Library/Python/2.7/site-packages/django/core/handlers/base.py", line 132, in get_response
    response = wrapped_callback(request, *callback_args, **callback_kwargs)
  File "/Users/Fan/Desktop/codes/NTCIRMDB2/user_system/utils.py", line 70, in ret
    return func(*args)
  File "/Users/Fan/Desktop/codes/NTCIRMDB2/assessment/views.py", line 16, in assessment
    user_name=set(list(usr.objects.values_list('usrid')))
  File "/Users/Fan/Desktop/codes/NTCIRMDB2/assessment/views.py", line 264, in set
    username=request.GET.get('username',None)
AttributeError: 'list' object has no attribute 'GET'
[08/Nov/2017 19:05:26] ERROR [django.request:256] Internal Server Error: /task/
Traceback (most recent call last):
  File "/Library/Python/2.7/site-packages/django/core/handlers/base.py", line 132, in get_response
    response = wrapped_callback(request, *callback_args, **callback_kwargs)
  File "/Users/Fan/Desktop/codes/NTCIRMDB2/user_system/utils.py", line 70, in ret
    return func(*args)
  File "/Users/Fan/Desktop/codes/NTCIRMDB2/assessment/views.py", line 16, in assessment
    user_name=set(list(usr.objects.values_list('usrid')))
  File "/Users/Fan/Desktop/codes/NTCIRMDB2/assessment/views.py", line 264, in set
    uname=request.GET.get('username',None)
AttributeError: 'list' object has no attribute 'GET'
[08/Nov/2017 19:06:30] ERROR [django.request:256] Internal Server Error: /task/
Traceback (most recent call last):
  File "/Library/Python/2.7/site-packages/django/core/handlers/base.py", line 132, in get_response
    response = wrapped_callback(request, *callback_args, **callback_kwargs)
  File "/Users/Fan/Desktop/codes/NTCIRMDB2/user_system/utils.py", line 70, in ret
    return func(*args)
  File "/Users/Fan/Desktop/codes/NTCIRMDB2/assessment/views.py", line 16, in assessment
    user_name=set(list(usr.objects.values_list('usrid')))
  File "/Users/Fan/Desktop/codes/NTCIRMDB2/user_system/utils.py", line 64, in ret
    assert isinstance(req, HttpRequest)
AssertionError
[08/Nov/2017 19:07:33] ERROR [django.request:256] Internal Server Error: /task/
Traceback (most recent call last):
  File "/Library/Python/2.7/site-packages/django/core/handlers/base.py", line 132, in get_response
    response = wrapped_callback(request, *callback_args, **callback_kwargs)
  File "/Users/Fan/Desktop/codes/NTCIRMDB2/user_system/utils.py", line 70, in ret
    return func(*args)
  File "/Users/Fan/Desktop/codes/NTCIRMDB2/assessment/views.py", line 16, in assessment
    user_name=set(list(usr.objects.values_list('usrid')))
  File "/Users/Fan/Desktop/codes/NTCIRMDB2/assessment/views.py", line 265, in set
    uname=request.GET.get('username',None)
AttributeError: 'list' object has no attribute 'GET'
[08/Nov/2017 19:08:13] ERROR [django.request:256] Internal Server Error: /task/
Traceback (most recent call last):
  File "/Library/Python/2.7/site-packages/django/core/handlers/base.py", line 132, in get_response
    response = wrapped_callback(request, *callback_args, **callback_kwargs)
  File "/Users/Fan/Desktop/codes/NTCIRMDB2/user_system/utils.py", line 70, in ret
    return func(*args)
  File "/Users/Fan/Desktop/codes/NTCIRMDB2/assessment/views.py", line 16, in assessment
    user_name=set(list(usr.objects.values_list('usrid')))
  File "/Users/Fan/Desktop/codes/NTCIRMDB2/assessment/views.py", line 265, in set
    uname=request.GET.get('username',None)
AttributeError: 'list' object has no attribute 'GET'
[08/Nov/2017 19:09:12] ERROR [django.request:256] Internal Server Error: /task/
Traceback (most recent call last):
  File "/Library/Python/2.7/site-packages/django/core/handlers/base.py", line 132, in get_response
    response = wrapped_callback(request, *callback_args, **callback_kwargs)
  File "/Users/Fan/Desktop/codes/NTCIRMDB2/user_system/utils.py", line 70, in ret
    return func(*args)
  File "/Users/Fan/Desktop/codes/NTCIRMDB2/assessment/views.py", line 16, in assessment
    user_name=set(list(usr.objects.values_list('usrid')))
  File "/Users/Fan/Desktop/codes/NTCIRMDB2/assessment/views.py", line 265, in set
    uname=request.GET.get('uname',None)
AttributeError: 'list' object has no attribute 'GET'
[08/Nov/2017 19:13:28] ERROR [django.request:256] Internal Server Error: /task/
Traceback (most recent call last):
  File "/Library/Python/2.7/site-packages/django/core/handlers/base.py", line 132, in get_response
    response = wrapped_callback(request, *callback_args, **callback_kwargs)
  File "/Users/Fan/Desktop/codes/NTCIRMDB2/user_system/utils.py", line 70, in ret
    return func(*args)
  File "/Users/Fan/Desktop/codes/NTCIRMDB2/assessment/views.py", line 16, in assessment
    user_name=set(list(usr.objects.values_list('usrid')))
  File "/Users/Fan/Desktop/codes/NTCIRMDB2/assessment/views.py", line 264, in set
    uname=request.GET.get('uname',None)
AttributeError: 'list' object has no attribute 'GET'
[08/Nov/2017 19:14:43] ERROR [django.request:256] Internal Server Error: /task/
Traceback (most recent call last):
  File "/Library/Python/2.7/site-packages/django/core/handlers/base.py", line 132, in get_response
    response = wrapped_callback(request, *callback_args, **callback_kwargs)
  File "/Users/Fan/Desktop/codes/NTCIRMDB2/user_system/utils.py", line 70, in ret
    return func(*args)
  File "/Users/Fan/Desktop/codes/NTCIRMDB2/assessment/views.py", line 16, in assessment
    user_name=set(list(usr.objects.values_list('usrid')))
  File "/Users/Fan/Desktop/codes/NTCIRMDB2/user_system/utils.py", line 64, in ret
    assert isinstance(req, HttpRequest)
AssertionError
[08/Nov/2017 19:15:28] ERROR [django.request:256] Internal Server Error: /task/
Traceback (most recent call last):
  File "/Library/Python/2.7/site-packages/django/core/handlers/base.py", line 132, in get_response
    response = wrapped_callback(request, *callback_args, **callback_kwargs)
  File "/Users/Fan/Desktop/codes/NTCIRMDB2/user_system/utils.py", line 70, in ret
    return func(*args)
  File "/Users/Fan/Desktop/codes/NTCIRMDB2/assessment/views.py", line 28, in assessment
    user_name=set(list(usr.objects.values_list('usrid')))
  File "/Users/Fan/Desktop/codes/NTCIRMDB2/assessment/views.py", line 14, in set
    uname=request.GET.get('uname',None)
AttributeError: 'list' object has no attribute 'GET'
[08/Nov/2017 19:18:15] ERROR [django.request:256] Internal Server Error: /task/
Traceback (most recent call last):
  File "/Library/Python/2.7/site-packages/django/core/handlers/base.py", line 132, in get_response
    response = wrapped_callback(request, *callback_args, **callback_kwargs)
  File "/Users/Fan/Desktop/codes/NTCIRMDB2/user_system/utils.py", line 70, in ret
    return func(*args)
  File "/Users/Fan/Desktop/codes/NTCIRMDB2/assessment/views.py", line 29, in assessment
    user_name=set(list(usr.objects.values_list('usrid')))
  File "/Users/Fan/Desktop/codes/NTCIRMDB2/assessment/views.py", line 15, in set
    uname=request.GET.get('uname',None)
AttributeError: 'list' object has no attribute 'GET'
[08/Nov/2017 19:18:22] ERROR [django.request:256] Internal Server Error: /task/
Traceback (most recent call last):
  File "/Library/Python/2.7/site-packages/django/core/handlers/base.py", line 132, in get_response
    response = wrapped_callback(request, *callback_args, **callback_kwargs)
  File "/Users/Fan/Desktop/codes/NTCIRMDB2/user_system/utils.py", line 70, in ret
    return func(*args)
  File "/Users/Fan/Desktop/codes/NTCIRMDB2/assessment/views.py", line 29, in assessment
    user_name=set(list(usr.objects.values_list('usrid')))
  File "/Users/Fan/Desktop/codes/NTCIRMDB2/assessment/views.py", line 15, in set
    uname=request.GET.get('uname',None)
AttributeError: 'list' object has no attribute 'GET'
[08/Nov/2017 19:19:22] ERROR [django.request:256] Internal Server Error: /task/
Traceback (most recent call last):
  File "/Library/Python/2.7/site-packages/django/core/handlers/base.py", line 132, in get_response
    response = wrapped_callback(request, *callback_args, **callback_kwargs)
  File "/Users/Fan/Desktop/codes/NTCIRMDB2/user_system/utils.py", line 70, in ret
    return func(*args)
  File "/Users/Fan/Desktop/codes/NTCIRMDB2/assessment/views.py", line 30, in assessment
    user_name=set(list(usr.objects.values_list('usrid')))
  File "/Users/Fan/Desktop/codes/NTCIRMDB2/assessment/views.py", line 15, in set
    uname=request.GET.get('uname',None)
AttributeError: 'list' object has no attribute 'GET'
[08/Nov/2017 19:20:27] ERROR [django.request:256] Internal Server Error: /task/
Traceback (most recent call last):
  File "/Library/Python/2.7/site-packages/django/core/handlers/base.py", line 132, in get_response
    response = wrapped_callback(request, *callback_args, **callback_kwargs)
  File "/Users/Fan/Desktop/codes/NTCIRMDB2/user_system/utils.py", line 70, in ret
    return func(*args)
  File "/Users/Fan/Desktop/codes/NTCIRMDB2/assessment/views.py", line 18, in assessment
    user_name=set(list(usr.objects.values_list('usrid')))
  File "/Users/Fan/Desktop/codes/NTCIRMDB2/assessment/views.py", line 264, in set
    uname=request.GET.get('uname',None)
AttributeError: 'list' object has no attribute 'GET'
[08/Nov/2017 19:20:33] ERROR [django.request:256] Internal Server Error: /task/
Traceback (most recent call last):
  File "/Library/Python/2.7/site-packages/django/core/handlers/base.py", line 132, in get_response
    response = wrapped_callback(request, *callback_args, **callback_kwargs)
  File "/Users/Fan/Desktop/codes/NTCIRMDB2/user_system/utils.py", line 70, in ret
    return func(*args)
  File "/Users/Fan/Desktop/codes/NTCIRMDB2/assessment/views.py", line 18, in assessment
    user_name=set(list(usr.objects.values_list('usrid')))
  File "/Users/Fan/Desktop/codes/NTCIRMDB2/assessment/views.py", line 264, in set
    uname=request.GET.get('uname',None)
AttributeError: 'list' object has no attribute 'GET'
[08/Nov/2017 19:26:23] ERROR [django.request:256] Internal Server Error: /task/
Traceback (most recent call last):
  File "/Library/Python/2.7/site-packages/django/core/handlers/base.py", line 132, in get_response
    response = wrapped_callback(request, *callback_args, **callback_kwargs)
  File "/Users/Fan/Desktop/codes/NTCIRMDB2/user_system/utils.py", line 70, in ret
    return func(*args)
  File "/Users/Fan/Desktop/codes/NTCIRMDB2/assessment/views.py", line 18, in assessment
    user_name=set(list(usr.objects.values_list('usrid')))
  File "/Users/Fan/Desktop/codes/NTCIRMDB2/assessment/views.py", line 264, in set
    uname=asd.GET.get('uname',None)
AttributeError: 'list' object has no attribute 'GET'
[08/Nov/2017 19:26:44] ERROR [django.request:256] Internal Server Error: /task/
Traceback (most recent call last):
  File "/Library/Python/2.7/site-packages/django/core/handlers/base.py", line 132, in get_response
    response = wrapped_callback(request, *callback_args, **callback_kwargs)
  File "/Users/Fan/Desktop/codes/NTCIRMDB2/user_system/utils.py", line 70, in ret
    return func(*args)
  File "/Users/Fan/Desktop/codes/NTCIRMDB2/assessment/views.py", line 18, in assessment
    user_name=set(list(usr.objects.values_list('usrid')))
  File "/Users/Fan/Desktop/codes/NTCIRMDB2/assessment/views.py", line 264, in set
    uname=asd.GET.get('uname',None)
AttributeError: 'list' object has no attribute 'GET'
[08/Nov/2017 19:29:03] ERROR [django.request:256] Internal Server Error: /task/
Traceback (most recent call last):
  File "/Library/Python/2.7/site-packages/django/core/handlers/base.py", line 132, in get_response
    response = wrapped_callback(request, *callback_args, **callback_kwargs)
  File "/Users/Fan/Desktop/codes/NTCIRMDB2/user_system/utils.py", line 70, in ret
    return func(*args)
  File "/Users/Fan/Desktop/codes/NTCIRMDB2/assessment/views.py", line 18, in assessment
    user_name=set(list(usr.objects.values_list('usrid')))
  File "/Users/Fan/Desktop/codes/NTCIRMDB2/assessment/views.py", line 264, in set
    uname=request.GET.get('uname',None)
AttributeError: 'list' object has no attribute 'GET'
[08/Nov/2017 19:29:20] ERROR [django.request:256] Internal Server Error: /task/
Traceback (most recent call last):
  File "/Library/Python/2.7/site-packages/django/core/handlers/base.py", line 132, in get_response
    response = wrapped_callback(request, *callback_args, **callback_kwargs)
  File "/Users/Fan/Desktop/codes/NTCIRMDB2/user_system/utils.py", line 70, in ret
    return func(*args)
  File "/Users/Fan/Desktop/codes/NTCIRMDB2/assessment/views.py", line 18, in assessment
    user_name=set(list(usr.objects.values_list('usrid')))
  File "/Users/Fan/Desktop/codes/NTCIRMDB2/assessment/views.py", line 264, in set
    uname=request.GET.get('uname',None)
AttributeError: 'list' object has no attribute 'GET'
[09/Nov/2017 16:00:03] ERROR [django.request:256] Internal Server Error: /task/
Traceback (most recent call last):
  File "/Library/Python/2.7/site-packages/django/core/handlers/base.py", line 132, in get_response
    response = wrapped_callback(request, *callback_args, **callback_kwargs)
  File "/Users/Fan/Desktop/codes/NTCIRMDB2/user_system/utils.py", line 70, in ret
    return func(*args)
  File "/Users/Fan/Desktop/codes/NTCIRMDB2/assessment/views.py", line 18, in assessment
    user_name=set(list(usr.objects.values_list('usrid')))
  File "/Users/Fan/Desktop/codes/NTCIRMDB2/assessment/views.py", line 265, in set
    uname=request.GET.get('uname',None)
AttributeError: 'list' object has no attribute 'GET'
[09/Nov/2017 16:08:56] ERROR [django.request:256] Internal Server Error: /task/
Traceback (most recent call last):
  File "/Library/Python/2.7/site-packages/django/core/handlers/base.py", line 132, in get_response
    response = wrapped_callback(request, *callback_args, **callback_kwargs)
  File "/Users/Fan/Desktop/codes/NTCIRMDB2/user_system/utils.py", line 70, in ret
    return func(*args)
  File "/Users/Fan/Desktop/codes/NTCIRMDB2/assessment/views.py", line 18, in assessment
    user_name=set(list(usr.objects.values_list('usrid')))
  File "/Users/Fan/Desktop/codes/NTCIRMDB2/assessment/views.py", line 265, in set
    uname=request.GET.get('uname',None)
AttributeError: 'list' object has no attribute 'GET'
[09/Nov/2017 16:14:22] ERROR [django.request:256] Internal Server Error: /task/
Traceback (most recent call last):
  File "/Library/Python/2.7/site-packages/django/core/handlers/base.py", line 132, in get_response
    response = wrapped_callback(request, *callback_args, **callback_kwargs)
  File "/Users/Fan/Desktop/codes/NTCIRMDB2/user_system/utils.py", line 70, in ret
    return func(*args)
  File "/Users/Fan/Desktop/codes/NTCIRMDB2/assessment/views.py", line 18, in assessment
    user_name=set(list(usr.objects.values_list('usrid')))
  File "/Users/Fan/Desktop/codes/NTCIRMDB2/assessment/views.py", line 265, in set
    uname=request.GET.get('uname',None)
AttributeError: 'list' object has no attribute 'GET'
[09/Nov/2017 16:14:31] ERROR [django.request:256] Internal Server Error: /task/
Traceback (most recent call last):
  File "/Library/Python/2.7/site-packages/django/core/handlers/base.py", line 132, in get_response
    response = wrapped_callback(request, *callback_args, **callback_kwargs)
  File "/Users/Fan/Desktop/codes/NTCIRMDB2/user_system/utils.py", line 70, in ret
    return func(*args)
  File "/Users/Fan/Desktop/codes/NTCIRMDB2/assessment/views.py", line 18, in assessment
    user_name=set(list(usr.objects.values_list('usrid')))
  File "/Users/Fan/Desktop/codes/NTCIRMDB2/assessment/views.py", line 265, in set
    uname=request.GET.get('uname',None)
AttributeError: 'list' object has no attribute 'GET'
[09/Nov/2017 16:14:34] ERROR [django.request:256] Internal Server Error: /task/
Traceback (most recent call last):
  File "/Library/Python/2.7/site-packages/django/core/handlers/base.py", line 132, in get_response
    response = wrapped_callback(request, *callback_args, **callback_kwargs)
  File "/Users/Fan/Desktop/codes/NTCIRMDB2/user_system/utils.py", line 70, in ret
    return func(*args)
  File "/Users/Fan/Desktop/codes/NTCIRMDB2/assessment/views.py", line 18, in assessment
    user_name=set(list(usr.objects.values_list('usrid')))
  File "/Users/Fan/Desktop/codes/NTCIRMDB2/assessment/views.py", line 265, in set
    uname=request.GET.get('uname',None)
AttributeError: 'list' object has no attribute 'GET'
[09/Nov/2017 16:14:37] ERROR [django.request:256] Internal Server Error: /task/
Traceback (most recent call last):
  File "/Library/Python/2.7/site-packages/django/core/handlers/base.py", line 132, in get_response
    response = wrapped_callback(request, *callback_args, **callback_kwargs)
  File "/Users/Fan/Desktop/codes/NTCIRMDB2/user_system/utils.py", line 70, in ret
    return func(*args)
  File "/Users/Fan/Desktop/codes/NTCIRMDB2/assessment/views.py", line 18, in assessment
    user_name=set(list(usr.objects.values_list('usrid')))
  File "/Users/Fan/Desktop/codes/NTCIRMDB2/assessment/views.py", line 265, in set
    uname=request.GET.get('uname',None)
AttributeError: 'list' object has no attribute 'GET'
[09/Nov/2017 16:17:05] ERROR [django.request:256] Internal Server Error: /task/
Traceback (most recent call last):
  File "/Library/Python/2.7/site-packages/django/core/handlers/base.py", line 132, in get_response
    response = wrapped_callback(request, *callback_args, **callback_kwargs)
  File "/Users/Fan/Desktop/codes/NTCIRMDB2/user_system/utils.py", line 70, in ret
    return func(*args)
  File "/Users/Fan/Desktop/codes/NTCIRMDB2/assessment/views.py", line 18, in assessment
    user_name=set(list(usr.objects.values_list('usrid')))
  File "/Users/Fan/Desktop/codes/NTCIRMDB2/user_system/utils.py", line 64, in ret
    assert isinstance(req, HttpRequest)
AssertionError
[09/Nov/2017 17:54:20] ERROR [django.request:256] Internal Server Error: /task/
Traceback (most recent call last):
  File "/Library/Python/2.7/site-packages/django/core/handlers/base.py", line 132, in get_response
    response = wrapped_callback(request, *callback_args, **callback_kwargs)
  File "/Users/Fan/Desktop/codes/NTCIRMDB2/user_system/utils.py", line 70, in ret
    return func(*args)
  File "/Users/Fan/Desktop/codes/NTCIRMDB2/assessment/views.py", line 22, in assessment
    return render(request, 'adminstrator.html', locals())
  File "/Library/Python/2.7/site-packages/django/shortcuts.py", line 67, in render
    template_name, context, request=request, using=using)
  File "/Library/Python/2.7/site-packages/django/template/loader.py", line 98, in render_to_string
    template = get_template(template_name, using=using)
  File "/Library/Python/2.7/site-packages/django/template/loader.py", line 35, in get_template
    return engine.get_template(template_name, dirs)
  File "/Library/Python/2.7/site-packages/django/template/backends/django.py", line 30, in get_template
    return Template(self.engine.get_template(template_name, dirs))
  File "/Library/Python/2.7/site-packages/django/template/engine.py", line 167, in get_template
    template, origin = self.find_template(template_name, dirs)
  File "/Library/Python/2.7/site-packages/django/template/engine.py", line 141, in find_template
    source, display_name = loader(name, dirs)
  File "/Library/Python/2.7/site-packages/django/template/loaders/base.py", line 13, in __call__
    return self.load_template(template_name, template_dirs)
  File "/Library/Python/2.7/site-packages/django/template/loaders/base.py", line 23, in load_template
    template = Template(source, origin, template_name, self.engine)
  File "/Library/Python/2.7/site-packages/django/template/base.py", line 191, in __init__
    self.nodelist = engine.compile_string(template_string, origin)
  File "/Library/Python/2.7/site-packages/django/template/engine.py", line 261, in compile_string
    return parser.parse()
  File "/Library/Python/2.7/site-packages/django/template/base.py", line 342, in parse
    compiled_result = compile_func(self, token)
  File "/Library/Python/2.7/site-packages/django/template/loader_tags.py", line 210, in do_extends
    nodelist = parser.parse()
  File "/Library/Python/2.7/site-packages/django/template/base.py", line 342, in parse
    compiled_result = compile_func(self, token)
  File "/Library/Python/2.7/site-packages/django/template/loader_tags.py", line 184, in do_block
    nodelist = parser.parse(('endblock',))
  File "/Library/Python/2.7/site-packages/django/template/base.py", line 342, in parse
    compiled_result = compile_func(self, token)
  File "/Library/Python/2.7/site-packages/django/template/defaulttags.py", line 872, in do_for
    nodelist_loop = parser.parse(('empty', 'endfor',))
  File "/Library/Python/2.7/site-packages/django/template/base.py", line 318, in parse
    filter_expression = self.compile_filter(token.contents)
  File "/Library/Python/2.7/site-packages/django/template/base.py", line 424, in compile_filter
    return FilterExpression(token, self)
  File "/Library/Python/2.7/site-packages/django/template/base.py", line 640, in __init__
    "from '%s'" % (token[upto:], token))
TemplateSyntaxError: Could not parse the remainder: '{{u' from 'user_dict.{{u'
[09/Nov/2017 19:19:40] WARNING [django.request:170] Not Found: /downaload/
[09/Nov/2017 19:20:10] WARNING [django.request:170] Not Found: /downaload/
[09/Nov/2017 19:20:39] ERROR [django.request:256] Internal Server Error: /download/
Traceback (most recent call last):
  File "/Library/Python/2.7/site-packages/django/core/handlers/base.py", line 132, in get_response
    response = wrapped_callback(request, *callback_args, **callback_kwargs)
  File "/Users/Fan/Desktop/codes/NTCIRMDB2/assessment/views.py", line 196, in download_csv
    f.write(file_name)
TypeError: expected a character buffer object
[09/Nov/2017 19:24:49] ERROR [django.request:256] Internal Server Error: /download/
Traceback (most recent call last):
  File "/Library/Python/2.7/site-packages/django/core/handlers/base.py", line 132, in get_response
    response = wrapped_callback(request, *callback_args, **callback_kwargs)
  File "/Users/Fan/Desktop/codes/NTCIRMDB2/assessment/views.py", line 198, in download_data
    return HttpResponse(f)
  File "/Library/Python/2.7/site-packages/django/http/response.py", line 342, in __init__
    self.content = content
  File "/Library/Python/2.7/site-packages/django/http/response.py", line 363, in content
    value = b''.join(self.make_bytes(chunk) for chunk in value)
ValueError: I/O operation on closed file
[09/Nov/2017 20:35:43] ERROR [django.request:256] Internal Server Error: /download/
Traceback (most recent call last):
  File "/Library/Python/2.7/site-packages/django/core/handlers/base.py", line 119, in get_response
    resolver_match = resolver.resolve(request.path_info)
  File "/Library/Python/2.7/site-packages/django/core/urlresolvers.py", line 367, in resolve
    sub_match = pattern.resolve(new_path)
  File "/Library/Python/2.7/site-packages/django/core/urlresolvers.py", line 239, in resolve
    return ResolverMatch(self.callback, args, kwargs, self.name)
  File "/Library/Python/2.7/site-packages/django/core/urlresolvers.py", line 246, in callback
    self._callback = get_callable(self._callback_str)
  File "/Library/Python/2.7/site-packages/django/utils/lru_cache.py", line 101, in wrapper
    result = user_function(*args, **kwds)
  File "/Library/Python/2.7/site-packages/django/core/urlresolvers.py", line 126, in get_callable
    (lookup_view, mod_name))
ViewDoesNotExist: Could not import 'assessment.views.download_data'. View does not exist in module assessment.views.
[09/Nov/2017 20:35:51] ERROR [django.request:256] Internal Server Error: /task/
Traceback (most recent call last):
  File "/Library/Python/2.7/site-packages/django/core/handlers/base.py", line 132, in get_response
    response = wrapped_callback(request, *callback_args, **callback_kwargs)
  File "/Users/Fan/Desktop/codes/NTCIRMDB2/user_system/utils.py", line 70, in ret
    return func(*args)
  File "/Users/Fan/Desktop/codes/NTCIRMDB2/assessment/views.py", line 19, in assessment
    user_name.remove('test01')
KeyError: 'test01'
[10/Nov/2017 15:43:15] ERROR [django.request:256] Internal Server Error: /task/
Traceback (most recent call last):
  File "/Library/Python/2.7/site-packages/django/core/handlers/base.py", line 132, in get_response
    response = wrapped_callback(request, *callback_args, **callback_kwargs)
  File "/Users/Fan/Desktop/codes/NTCIRMDB2/user_system/utils.py", line 70, in ret
    return func(*args)
  File "/Users/Fan/Desktop/codes/NTCIRMDB2/assessment/views.py", line 19, in assessment
    user_name.remove('test01')
KeyError: 'test01'
[10/Nov/2017 15:47:08] ERROR [django.request:256] Internal Server Error: /task/
Traceback (most recent call last):
  File "/Library/Python/2.7/site-packages/django/core/handlers/base.py", line 132, in get_response
    response = wrapped_callback(request, *callback_args, **callback_kwargs)
  File "/Users/Fan/Desktop/codes/NTCIRMDB2/user_system/utils.py", line 70, in ret
    return func(*args)
  File "/Users/Fan/Desktop/codes/NTCIRMDB2/assessment/views.py", line 28, in assessment
    l.append(int(g))
ValueError: invalid literal for int() with base 10: ")('&%"
[17/Dec/2017 15:56:47] ERROR [django.request:256] Internal Server Error: /download/
Traceback (most recent call last):
  File "/Library/Python/2.7/site-packages/django/core/handlers/base.py", line 132, in get_response
    response = wrapped_callback(request, *callback_args, **callback_kwargs)
  File "/Users/Fan/Desktop/codes/NTCIRMDB2/assessment/views.py", line 209, in download_data
    return HttpResponse(f)
  File "/Library/Python/2.7/site-packages/django/http/response.py", line 342, in __init__
    self.content = content
  File "/Library/Python/2.7/site-packages/django/http/response.py", line 363, in content
    value = b''.join(self.make_bytes(chunk) for chunk in value)
ValueError: I/O operation on closed file
[17/Dec/2017 15:56:48] WARNING [django.request:170] Not Found: /favicon.ico
[17/Dec/2017 15:58:43] ERROR [django.request:256] Internal Server Error: /download/
Traceback (most recent call last):
  File "/Library/Python/2.7/site-packages/django/core/handlers/base.py", line 132, in get_response
    response = wrapped_callback(request, *callback_args, **callback_kwargs)
  File "/Users/Fan/Desktop/codes/NTCIRMDB2/assessment/views.py", line 208, in download_data
    return HttpResponse(f)
  File "/Library/Python/2.7/site-packages/django/http/response.py", line 342, in __init__
    self.content = content
  File "/Library/Python/2.7/site-packages/django/http/response.py", line 363, in content
    value = b''.join(self.make_bytes(chunk) for chunk in value)
  File "/Library/Python/2.7/site-packages/django/http/response.py", line 363, in <genexpr>
    value = b''.join(self.make_bytes(chunk) for chunk in value)
IOError: File not open for reading
[17/Dec/2017 19:00:53] ERROR [django.request:256] Internal Server Error: /download/
Traceback (most recent call last):
  File "/Library/Python/2.7/site-packages/django/core/handlers/base.py", line 132, in get_response
    response = wrapped_callback(request, *callback_args, **callback_kwargs)
  File "/Users/Fan/Desktop/codes/NTCIRMDB2/assessment/views.py", line 215, in download_data
    d1 = open('/home/fanyimeng/exdocument.txt')
IOError: [Errno 2] No such file or directory: '/home/fanyimeng/exdocument.txt'
